Error building categorical dataset:
Traceback (most recent call last):
  File "/Users/abelguevarah/Desktop/IA/.venv/lib/python3.12/site-packages/pandas/core/indexes/base.py", line 3812, in get_loc
    return self._engine.get_loc(casted_key)
           ^^^^^^^^^^^^^^^^^^^^^^^^^^^^^^^^
  File "pandas/_libs/index.pyx", line 167, in pandas._libs.index.IndexEngine.get_loc
  File "pandas/_libs/index.pyx", line 196, in pandas._libs.index.IndexEngine.get_loc
  File "pandas/_libs/hashtable_class_helper.pxi", line 7088, in pandas._libs.hashtable.PyObjectHashTable.get_item
  File "pandas/_libs/hashtable_class_helper.pxi", line 7096, in pandas._libs.hashtable.PyObjectHashTable.get_item
KeyError: 'horas_pantalla_no_academica'

The above exception was the direct cause of the following exception:

Traceback (most recent call last):
  File "/Users/abelguevarah/Desktop/IA/p2/resources/generate_simulated_dataset.py", line 578, in <module>
    p = df['horas_pantalla_no_academica']
        ~~^^^^^^^^^^^^^^^^^^^^^^^^^^^^^^^
  File "/Users/abelguevarah/Desktop/IA/.venv/lib/python3.12/site-packages/pandas/core/frame.py", line 4113, in __getitem__
    indexer = self.columns.get_loc(key)
              ^^^^^^^^^^^^^^^^^^^^^^^^^
  File "/Users/abelguevarah/Desktop/IA/.venv/lib/python3.12/site-packages/pandas/core/indexes/base.py", line 3819, in get_loc
    raise KeyError(key) from err
KeyError: 'horas_pantalla_no_academica'
